<?xml version="1.0"?>
<!--
  hermes_sim.urdf.xacro
  =====================
  Simulation URDF for the HERMES differential-drive robot.
  Designed for Gazebo Harmonic (gz-sim) with ROS 2 Jazzy.

  TF tree produced at runtime
  ---------------------------
    odom  ←─ (DiffDrive plugin via /tf bridge)
      └── base_footprint
            └── base_link
                  ├── wheel_left_link
                  ├── wheel_right_link
                  ├── caster_link
                  ├── laser_frame   (LiDAR at z=0.18 m)
                  └── camera_frame  (camera at x=0.05, z=0.20 m)

  Topics
  ------
    /cmd_vel          geometry_msgs/Twist   → drive command (ROS → gz)
    /odom             nav_msgs/Odometry     ← wheel odometry  (gz → ROS)
    /scan             sensor_msgs/LaserScan ← 360° LiDAR      (gz → ROS)
    /tf               tf2_msgs/TFMessage    ← odom→base_footprint (gz → ROS)
    /joint_states     sensor_msgs/JointState ← wheel joints   (gz → ROS)
-->
<robot name="hermes" xmlns:xacro="http://www.ros.org/wiki/xacro">

  <!-- ── Constants ───────────────────────────────────────────────────────── -->
  <xacro:property name="PI"               value="3.14159265359"/>
  <xacro:property name="base_radius"      value="0.18"/>   <!-- m  -->
  <xacro:property name="base_height"      value="0.15"/>   <!-- m  -->
  <xacro:property name="wheel_radius"     value="0.05"/>   <!-- m  -->
  <xacro:property name="wheel_width"      value="0.04"/>   <!-- m  -->
  <xacro:property name="wheel_separation" value="0.30"/>   <!-- m  -->

  <!-- ── base_footprint ─────────────────────────────────────────────────── -->
  <link name="base_footprint"/>

  <joint name="base_footprint_joint" type="fixed">
    <parent link="base_footprint"/>
    <child  link="base_link"/>
    <origin xyz="0 0 ${wheel_radius}" rpy="0 0 0"/>
  </joint>

  <!-- ── base_link (cylindrical body) ──────────────────────────────────── -->
  <link name="base_link">
    <visual>
      <geometry>
        <cylinder radius="${base_radius}" length="${base_height}"/>
      </geometry>
      <material name="dark_grey">
        <color rgba="0.3 0.3 0.3 1.0"/>
      </material>
    </visual>
    <collision>
      <geometry>
        <cylinder radius="${base_radius}" length="${base_height}"/>
      </geometry>
    </collision>
    <inertial>
      <mass value="5.0"/>
      <!-- Solid cylinder: Ixx=Iyy=m(3r²+h²)/12, Izz=mr²/2 -->
      <inertia ixx="0.0607" ixy="0.0" ixz="0.0"
               iyy="0.0607" iyz="0.0"
               izz="0.0810"/>
    </inertial>
  </link>

  <!-- ── Left wheel ─────────────────────────────────────────────────────── -->
  <link name="wheel_left_link">
    <visual>
      <origin xyz="0 0 0" rpy="${PI/2} 0 0"/>
      <geometry>
        <cylinder radius="${wheel_radius}" length="${wheel_width}"/>
      </geometry>
      <material name="black">
        <color rgba="0.1 0.1 0.1 1.0"/>
      </material>
    </visual>
    <collision>
      <origin xyz="0 0 0" rpy="${PI/2} 0 0"/>
      <geometry>
        <cylinder radius="${wheel_radius}" length="${wheel_width}"/>
      </geometry>
    </collision>
    <inertial>
      <mass value="0.5"/>
      <inertia ixx="0.00052" ixy="0.0" ixz="0.0"
               iyy="0.00052" iyz="0.0"
               izz="0.00063"/>
    </inertial>
  </link>

  <joint name="wheel_left_joint" type="continuous">
    <parent link="base_link"/>
    <child  link="wheel_left_link"/>
    <origin xyz="0 ${wheel_separation/2} 0" rpy="0 0 0"/>
    <axis xyz="0 1 0"/>
  </joint>

  <!-- ── Right wheel ────────────────────────────────────────────────────── -->
  <link name="wheel_right_link">
    <visual>
      <origin xyz="0 0 0" rpy="${PI/2} 0 0"/>
      <geometry>
        <cylinder radius="${wheel_radius}" length="${wheel_width}"/>
      </geometry>
      <material name="black">
        <color rgba="0.1 0.1 0.1 1.0"/>
      </material>
    </visual>
    <collision>
      <origin xyz="0 0 0" rpy="${PI/2} 0 0"/>
      <geometry>
        <cylinder radius="${wheel_radius}" length="${wheel_width}"/>
      </geometry>
    </collision>
    <inertial>
      <mass value="0.5"/>
      <inertia ixx="0.00052" ixy="0.0" ixz="0.0"
               iyy="0.00052" iyz="0.0"
               izz="0.00063"/>
    </inertial>
  </link>

  <joint name="wheel_right_joint" type="continuous">
    <parent link="base_link"/>
    <child  link="wheel_right_link"/>
    <origin xyz="0 ${-wheel_separation/2} 0" rpy="0 0 0"/>
    <axis xyz="0 1 0"/>
  </joint>

  <!-- ── Caster wheel (passive ball, zero friction) ─────────────────────── -->
  <link name="caster_link">
    <visual>
      <geometry>
        <sphere radius="${wheel_radius/2}"/>
      </geometry>
      <material name="light_grey">
        <color rgba="0.6 0.6 0.6 1.0"/>
      </material>
    </visual>
    <collision>
      <geometry>
        <sphere radius="${wheel_radius/2}"/>
      </geometry>
    </collision>
    <inertial>
      <mass value="0.1"/>
      <inertia ixx="0.00001" ixy="0.0" ixz="0.0"
               iyy="0.00001" iyz="0.0"
               izz="0.00001"/>
    </inertial>
  </link>

  <joint name="caster_joint" type="fixed">
    <parent link="base_link"/>
    <child  link="caster_link"/>
    <!-- Rear of base, resting on the ground -->
    <origin xyz="${-(base_radius - wheel_radius/2)} 0 ${-(base_height/2 - wheel_radius/2)}"
            rpy="0 0 0"/>
  </joint>

  <!-- ── laser_frame (2-D LiDAR) ───────────────────────────────────────── -->
  <link name="laser_frame">
    <visual>
      <geometry>
        <cylinder radius="0.04" length="0.04"/>
      </geometry>
      <material name="blue">
        <color rgba="0.0 0.4 0.8 1.0"/>
      </material>
    </visual>
    <collision>
      <geometry>
        <cylinder radius="0.04" length="0.04"/>
      </geometry>
    </collision>
    <inertial>
      <mass value="0.1"/>
      <inertia ixx="0.00001" ixy="0.0" ixz="0.0"
               iyy="0.00001" iyz="0.0"
               izz="0.00001"/>
    </inertial>
  </link>

  <joint name="laser_joint" type="fixed">
    <parent link="base_link"/>
    <child  link="laser_frame"/>
    <origin xyz="0 0 0.18" rpy="0 0 0"/>
  </joint>

  <!-- ── camera_frame ──────────────────────────────────────────────────── -->
  <link name="camera_frame">
    <visual>
      <geometry>
        <box size="0.03 0.03 0.03"/>
      </geometry>
      <material name="red">
        <color rgba="0.8 0.1 0.1 1.0"/>
      </material>
    </visual>
    <inertial>
      <mass value="0.05"/>
      <inertia ixx="0.00001" ixy="0.0" ixz="0.0"
               iyy="0.00001" iyz="0.0"
               izz="0.00001"/>
    </inertial>
  </link>

  <joint name="camera_joint" type="fixed">
    <parent link="base_link"/>
    <child  link="camera_frame"/>
    <origin xyz="0.05 0 0.20" rpy="0 0 0"/>
  </joint>

  <!-- ══════════════════════════════════════════════════════════════════════
       Gazebo Harmonic (gz-sim) plugins
       ══════════════════════════════════════════════════════════════════════ -->

  <!-- Differential drive controller ──────────────────────────────────────── -->
  <gazebo>
    <plugin filename="gz-sim-diff-drive-system"
            name="gz::sim::systems::DiffDrive">
      <left_joint>wheel_left_joint</left_joint>
      <right_joint>wheel_right_joint</right_joint>
      <wheel_separation>${wheel_separation}</wheel_separation>
      <wheel_radius>${wheel_radius}</wheel_radius>
      <odom_publish_frequency>20</odom_publish_frequency>
      <!-- Topics (bridged to ROS 2 by ros_gz_bridge) -->
      <topic>cmd_vel</topic>
      <odom_topic>odom</odom_topic>
      <tf_topic>tf</tf_topic>
      <frame_id>odom</frame_id>
      <child_frame_id>base_footprint</child_frame_id>
      <min_velocity>-0.5</min_velocity>
      <max_velocity>0.5</max_velocity>
      <min_acceleration>-1.0</min_acceleration>
      <max_acceleration>1.0</max_acceleration>
    </plugin>

    <!-- Joint state publisher for wheel joints -->
    <plugin filename="gz-sim-joint-state-publisher-system"
            name="gz::sim::systems::JointStatePublisher">
      <topic>joint_states</topic>
      <joint_name>wheel_left_joint</joint_name>
      <joint_name>wheel_right_joint</joint_name>
    </plugin>
  </gazebo>

  <!-- Zero friction on the caster so it slides freely ───────────────────── -->
  <gazebo reference="caster_link">
    <mu1>0.0</mu1>
    <mu2>0.0</mu2>
  </gazebo>

  <!-- 2-D LiDAR (360°, 10 Hz, 12 m range) ─────────────────────────────── -->
  <gazebo reference="laser_frame">
    <sensor name="lidar" type="gpu_lidar">
      <topic>/scan</topic>
      <update_rate>10</update_rate>
      <always_on>true</always_on>
      <visualize>false</visualize>
      <gz_frame_id>laser_frame</gz_frame_id>
      <lidar>
        <scan>
          <horizontal>
            <samples>360</samples>
            <resolution>1</resolution>
            <min_angle>-3.14159265</min_angle>
            <max_angle>3.14159265</max_angle>
          </horizontal>
        </scan>
        <range>
          <min>0.10</min>
          <max>12.0</max>
          <resolution>0.01</resolution>
        </range>
        <noise>
          <type>gaussian</type>
          <mean>0.0</mean>
          <stddev>0.01</stddev>
        </noise>
      </lidar>
    </sensor>
  </gazebo>

</robot>
